<?xml version="1.0" ?>

<robot name="bot_main" xmlns:xacro="https://www.ros.org/wiki/xacro" >

  <xacro:include filename="$(find umic)/urdf/materials.xacro"/>
  <xacro:include filename="$(find umic)/urdf/umic_gazebo.xacro"/>

  <link name="base_link">
    <pose>0 0 0.2 0 0 0</pose>
    <inertial>
      <mass value="5"/>
      <origin rpy="0 0 0" xyz="0 0 0.1"/>
      <inertia ixx="0.03954166" ixy="0" ixz="0" iyy="0.10620833" iyz="0"  izz="0.1062083"/>
    </inertial>

    <collision name="collision_chassis">
      <origin rpy="0 0 0" xyz="0 0 0"/>
      <geometry>
        <box size="0.3 0.3 0.2"/>
      </geometry>
    </collision>

    <visual>
      <origin rpy="0 0 0" xyz="0 0 0"/>
      <geometry>
        <box size="0.3 0.3 0.2"/>
      </geometry>
      <material name="blue"/>
    </visual>

    <collision>
      <origin rpy="0 1.5707 1.5707" xyz="-0.13 0.15 -0.1" />
      <geometry>
        <cylinder length="0.04" radius="0.07"/>
      </geometry>
      <surface>
        <friction>
          <ode>
            <mu>0</mu>
            <mu2>0</mu2>
            <slip1>1.0</slip1>
            <slip2>1.0</slip2>
          </ode>
        </friction>
      </surface>
    </collision>

    <visual>
      <origin rpy="0 1.5707 1.5707" xyz="-0.13 0.15 -0.1"/>
      <geometry>
        <cylinder length="0.04" radius="0.07"/>
      </geometry>
    </visual>

    <collision>
      <origin rpy="0 1.5707 1.5707" xyz="-0.13 -0.15 -0.1" />
      <geometry>
        <cylinder length="0.04" radius="0.07"/>
      </geometry>
      <surface>
        <friction>
          <ode>
            <mu>0</mu>
            <mu2>0</mu2>
            <slip1>1.0</slip1>
            <slip2>1.0</slip2>
          </ode>
        </friction>
      </surface>
    </collision>

    <visual>
      <origin rpy="0 1.5707 1.5707" xyz="-0.13 -0.15 -0.1"/>
      <geometry>
        <cylinder length="0.04" radius="0.07"/>
      </geometry>
    </visual>
  </link>


  <xacro:macro name="wheel" params="wheel_name">
    <link name="${wheel_name}">
      <inertial>
        <mass value="0.2"/>
        <origin rpy="0 1.5707 1.5707" xyz="0 0 0"/>
        <inertia ixx="0.0012" ixy="0" ixz="0" iyy="0.0012" iyz="0" izz="0.002"/>
      </inertial>

      <collision>
        <origin rpy="0 1.5707 1.5707" xyz="0 0 0" />
        <geometry>
          <cylinder length="0.04" radius="0.07"/>
        </geometry>
      </collision>

      <visual>
        <origin rpy="0 1.5707 1.5707" xyz="0 0 0"/>
        <geometry>
          <cylinder length="0.04" radius="0.07"/>
        </geometry>
      </visual>
   </link>
  </xacro:macro>

  <xacro:wheel wheel_name="wheel_left">
  </xacro:wheel>
  <xacro:wheel wheel_name="wheel_right">
  </xacro:wheel>

  <xacro:macro name="wheel_chassis_joint" params="joint_name child_link *origin">
    <joint name="${joint_name}" type="continuous">
      <xacro:insert_block name="origin"/>
      <parent link="base_link"/>
      <child link="${child_link}"/>
      <axis rpy="0 0 0" xyz="0 1 0"/>
      <limit effort="10000" velocity="1000"/>
      <joint_properties damping="1.0" friction="1.0" />
    </joint>
  </xacro:macro>

  <xacro:wheel_chassis_joint joint_name="wheel_left_chassis" child_link="wheel_left">
    <origin xyz="0.13 0.15 -0.1" rpy="0 0 0"/>
  </xacro:wheel_chassis_joint>

  <xacro:wheel_chassis_joint joint_name="wheel_right_chassis" child_link="wheel_right">
    <origin xyz="0.13 -0.15 -0.1" rpy="0 0 0"/>
  </xacro:wheel_chassis_joint>


  <link name="horizontal_slider">
    <inertial>
      <mass value="0.5"/>
      <origin xyz="0 0 0" rpy="0 0 0"/>
      <inertia ixx="0.1" ixy="0" ixz="0" iyy="0.1" iyz="0" izz="0.1"/>
    </inertial>

    <collision>
      <origin xyz="0 0 0" rpy="0 0 0"/>
      <geometry>
        <box size="0.6 0.04 0.04"/>
      </geometry>
    </collision>

    <visual>
      <origin xyz="0 0 0" rpy="0 0 0"/>
      <geometry>
        <box size="0.6 0.04 0.04"/>
      </geometry>
    </visual>
  </link>

  <joint name="slider_on_bot" type="prismatic">
    <origin xyz="0 0 0.1" rpy="0 0 0"/>
    <parent link="base_link"/>
    <child link="horizontal_slider"/>
    <axis rpy="0 0 0" xyz="1 0 0"/>
    <limit lower="-0.04" upper="0.10" effort="10000" velocity="1000"/>
    <joint_properties damping="1.0" friction="1.0" />
  </joint>

  <link name="palm">
    <inertial>
      <mass value="0.01"/>
      <origin xyz="0 0 0.05" rpy="0 0 0"/>
      <inertia ixx="0.01" ixy="0" ixz="0" iyy="0.01" iyz="0" izz="0.01"/>
    </inertial>
    <collision>
      <origin xyz="0 0 0" rpy="0 0 0"/>
      <geometry>
        <box size="0.05 0.2 0.05"/>
      </geometry>
    </collision>
    <visual>
      <origin xyz="0 0 0" rpy="0 0 0"/>
      <geometry>
        <box size="0.05 0.2 0.05"/>
      </geometry>
    </visual>
  </link>

  <link name="left_finger">
    <inertial>
      <mass value="0.01"/>
      <origin xyz="0 0 0" rpy="0 0 0"/>
      <inertia ixx="0.01" ixy="0" ixz="0" iyy="0.01" iyz="0" izz="0"/>
    </inertial>
    <collision>
      <origin xyz="0 -0.1 0" rpy="0 0 0"/>
      <geometry>
        <box size="0.05 0.2 0.05"/>
      </geometry>
    </collision>
    <visual>
      <origin xyz="0 -0.1 0" rpy="0 0 0"/>
      <geometry>
        <box size="0.05 0.2 0.05"/>
      </geometry>
    </visual>
  </link>

  <link name="right_finger">
    <inertial>
      <mass value="0.01"/>
      <origin xyz="0 0 0" rpy="0 0 0"/>
      <inertia ixx="0.01" ixy="0" ixz="0" iyy="0.01" iyz="0" izz="0"/>
    </inertial>
    <collision>
      <origin xyz="0 0.1 0" rpy="0 0 0"/>
      <geometry>
        <box size="0.05 0.2 0.05"/>
      </geometry>
    </collision>
    <visual>
      <origin xyz="0 0.1 0" rpy="0 0 0"/>
      <geometry>
        <box size="0.05 0.2 0.05"/>
      </geometry>
    </visual>
  </link>

  <link name="left_finger_tip">
    <inertial>
      <origin xyz="0 0 0" rpy="0 0 0"/>
      <mass value="0.01"/>
      <inertia ixx="0.01" ixy="0" ixz="0" iyy="0.01" iyz="0" izz="0.01"/>
    </inertial>
    <collision>
      <origin xyz="0 -0.05 0" rpy="0 0 0"/>
      <geometry>
        <box size="0.05 0.1 0.05"/>
      </geometry>
    </collision>
    <visual>
      <origin xyz="0 -0.05 0" rpy="0 0 0"/>
      <geometry>
        <box size="0.05 0.1 0.05"/>
      </geometry>
    </visual>
  </link>

  <link name="right_finger_tip">
    <inertial>
      <origin xyz="0 0 0" rpy="0 0 0"/>
      <mass value="0.01"/>
      <inertia ixx="0.01" ixy="0" ixz="0" iyy="0.01" iyz="0" izz="0.01"/>
    </inertial>
    <collision>
      <origin xyz="0 0.05 0" rpy="0 0 0"/>
      <geometry>
        <box size="0.05 0.1 0.05"/>
      </geometry>
    </collision>
    <visual>
      <origin xyz="0 0.05 0" rpy="0 0 0"/>
      <geometry>
        <box size="0.05 0.1 0.05"/>
      </geometry>
    </visual>
  </link>

  <joint name="palm_left_finger" type="revolute">
    <origin xyz="0 -0.08 0" rpy="0 0 0.78"/>
    <child link="left_finger"/>
    <parent link="palm"/>
    <axis xyz="0 0 1" />
    <limit lower="0" upper="0.72" effort="10" velocity="10"/>
  </joint>

  <joint name="left_finger_tip" type="fixed">
    <origin xyz="0 -0.18 0" rpy="0 0 0.78"/>
    <child link="left_finger_tip"/>
    <parent link="left_finger"/>
  </joint>

  <joint name="palm_right_finger" type="revolute">
    <origin xyz="0 0.08 0" rpy="0 0 -0.78"/>
    <child link="right_finger"/>
    <parent link="palm"/>
    <axis xyz="0 0 1" />
    <limit lower="-0.72" upper="0" effort="10" velocity="10"/>
  </joint>

  <joint name="right_finger_tip" type="fixed">
    <origin xyz="0 0.18 0" rpy="0 0 -0.78"/>
    <child link="right_finger_tip"/>
    <parent link="right_finger"/>
  </joint>

  <joint name="palm_slider" type="fixed">
    <origin xyz="0.3 0 0" rpy="0 0 0"/>
    <child link="palm"/>
    <parent link="horizontal_slider"/>
  </joint>


  <xacro:property name="camera_link" value="0.05"/>

  <!--CAMERA_LINK-->
  <joint name="camera_joint" type="fixed">
    <axis xyz="0 1 0" />
    <origin xyz="0.15 0 0" rpy="0 0 0"/>
    <parent link="base_link"/>
    <child link="camera_link"/>
  </joint>

  <!-- Camera -->
  <link name="camera_link">
    <collision>
      <origin xyz="0 0 0" rpy="0 0 0"/>
      <geometry>
    <box size="${camera_link} ${camera_link} ${camera_link}"/>
      </geometry>
    </collision>

    <visual>
      <origin xyz="0 0 0" rpy="0 0 0"/>
      <geometry>
    <box size="${camera_link} ${camera_link} ${camera_link}"/>
      </geometry>
      <material name="red"/>
    </visual>

    <inertial>
      <mass value="1e-5" />
      <origin xyz="0 0 0" rpy="0 0 0"/>
      <inertia ixx="1e-6" ixy="0" ixz="0" iyy="1e-6" iyz="0" izz="1e-6" />
    </inertial>
  </link>

</robot>
