<?xml version="1.0" ?>
<!-- =================================================================================== -->
<!-- |    This document was autogenerated by xacro from bot_main.xacro                 | -->
<!-- |    EDITING THIS FILE BY HAND IS NOT RECOMMENDED                                 | -->
<!-- =================================================================================== -->
<robot name="m2wr" xmlns:xacro="https://www.ros.org/wiki/xacro">
  <material name="black">
    <color rgba="0.0 0.0 0.0 1.0"/>
  </material>
  <material name="blue">
    <color rgba="0.203125 0.23828125 0.28515625 1.0"/>
  </material>
  <material name="green">
    <color rgba="0.0 0.8 0.0 1.0"/>
  </material>
  <material name="grey">
    <color rgba="0.2 0.2 0.2 1.0"/>
  </material>
  <material name="orange">
    <color rgba="1.0 0.423529411765 0.0392156862745 1.0"/>
  </material>
  <material name="brown">
    <color rgba="0.870588235294 0.811764705882 0.764705882353 1.0"/>
  </material>
  <material name="red">
    <color rgba="0.80078125 0.12890625 0.1328125 1.0"/>
  </material>
  <material name="white">
    <color rgba="1.0 1.0 1.0 1.0"/>
  </material>
  <gazebo reference="base_link">
    <material>Gazebo/Orange</material>
  </gazebo>
  <gazebo reference="wheel_left">
    <material>Gazebo/Blue</material>
  </gazebo>
  <gazebo reference="wheel_right">
    <material>Gazebo/Blue</material>
  </gazebo>
  <gazebo reference="horizontal_slider">
    <material>Gazebo/Green</material>
  </gazebo>
  <gazebo reference="palm">
    <material>Gazebo/Green</material>
  </gazebo>
  <gazebo reference="left_finger">
    <material>Gazebo/Red</material>
  </gazebo>
  <gazebo reference="right_finger">
    <material>Gazebo/Red</material>
  </gazebo>
  <gazebo reference="left_finger_tip">
    <material>Gazebo/Yellow</material>
  </gazebo>
  <gazebo reference="right_finger_tip">
    <material>Gazebo/Yellow</material>
  </gazebo>
  <gazebo>
    <plugin filename="libgazebo_ros_diff_drive.so" name="differential_drive_controller">
      <legacyMode>false</legacyMode>
      <alwaysOn>true</alwaysOn>
      <updateRate>20</updateRate>
      <leftJoint>wheel_left_chassis</leftJoint>
      <rightJoint>wheel_right_chassis</rightJoint>
      <wheelSeparation>0.3</wheelSeparation>
      <wheelDiameter>0.2</wheelDiameter>
      <torque>0.1</torque>
      <commandTopic>cmd_vel</commandTopic>
      <odometryTopic>odom</odometryTopic>
      <odometryFrame>odom</odometryFrame>
      <robotBaseFrame>base_link</robotBaseFrame>
    </plugin>
  </gazebo>
  <link name="base_link">
    <pose>0 0 0.2 0 0 0</pose>
    <inertial>
      <mass value="5"/>
      <origin rpy="0 0 0" xyz="0 0 0.1"/>
      <inertia ixx="0.03954166" ixy="0" ixz="0" iyy="0.10620833" iyz="0" izz="0.1062083"/>
    </inertial>
    <collision name="collision_chassis">
      <origin rpy="0 0 0" xyz="0 0 0"/>
      <geometry>
        <box size="0.3 0.3 0.2"/>
      </geometry>
    </collision>
    <visual>
      <origin rpy="0 0 0" xyz="0 0 0"/>
      <geometry>
        <box size="0.3 0.3 0.2"/>
      </geometry>
      <material name="blue"/>
    </visual>
    <collision>
      <origin rpy="0 1.5707 1.5707" xyz="-0.13 0.15 -0.1"/>
      <geometry>
        <cylinder length="0.04" radius="0.07"/>
      </geometry>
      <surface>
        <friction>
          <ode>
            <mu>0</mu>
            <mu2>0</mu2>
            <slip1>1.0</slip1>
            <slip2>1.0</slip2>
          </ode>
        </friction>
      </surface>
    </collision>
    <visual>
      <origin rpy="0 1.5707 1.5707" xyz="-0.13 0.15 -0.1"/>
      <geometry>
        <cylinder length="0.04" radius="0.07"/>
      </geometry>
    </visual>
    <collision>
      <origin rpy="0 1.5707 1.5707" xyz="-0.13 -0.15 -0.1"/>
      <geometry>
        <cylinder length="0.04" radius="0.07"/>
      </geometry>
      <surface>
        <friction>
          <ode>
            <mu>0</mu>
            <mu2>0</mu2>
            <slip1>1.0</slip1>
            <slip2>1.0</slip2>
          </ode>
        </friction>
      </surface>
    </collision>
    <visual>
      <origin rpy="0 1.5707 1.5707" xyz="-0.13 -0.15 -0.1"/>
      <geometry>
        <cylinder length="0.04" radius="0.07"/>
      </geometry>
    </visual>
  </link>
  <link name="wheel_left">
    <inertial>
      <mass value="0.2"/>
      <origin rpy="0 1.5707 1.5707" xyz="0 0 0"/>
      <inertia ixx="0.0012" ixy="0" ixz="0" iyy="0.0012" iyz="0" izz="0.002"/>
    </inertial>
    <collision>
      <origin rpy="0 1.5707 1.5707" xyz="0 0 0"/>
      <geometry>
        <cylinder length="0.04" radius="0.07"/>
      </geometry>
    </collision>
    <visual>
      <origin rpy="0 1.5707 1.5707" xyz="0 0 0"/>
      <geometry>
        <cylinder length="0.04" radius="0.07"/>
      </geometry>
    </visual>
  </link>
  <link name="wheel_right">
    <inertial>
      <mass value="0.2"/>
      <origin rpy="0 1.5707 1.5707" xyz="0 0 0"/>
      <inertia ixx="0.0012" ixy="0" ixz="0" iyy="0.0012" iyz="0" izz="0.002"/>
    </inertial>
    <collision>
      <origin rpy="0 1.5707 1.5707" xyz="0 0 0"/>
      <geometry>
        <cylinder length="0.04" radius="0.07"/>
      </geometry>
    </collision>
    <visual>
      <origin rpy="0 1.5707 1.5707" xyz="0 0 0"/>
      <geometry>
        <cylinder length="0.04" radius="0.07"/>
      </geometry>
    </visual>
  </link>
  <joint name="wheel_left_chassis" type="continuous">
    <origin rpy="0 0 0" xyz="0.13 0.15 -0.1"/>
    <parent link="base_link"/>
    <child link="wheel_left"/>
    <axis rpy="0 0 0" xyz="0 1 0"/>
    <limit effort="10000" velocity="1000"/>
    <joint_properties damping="1.0" friction="1.0"/>
  </joint>
  <joint name="wheel_right_chassis" type="continuous">
    <origin rpy="0 0 0" xyz="0.13 -0.15 -0.1"/>
    <parent link="base_link"/>
    <child link="wheel_right"/>
    <axis rpy="0 0 0" xyz="0 1 0"/>
    <limit effort="10000" velocity="1000"/>
    <joint_properties damping="1.0" friction="1.0"/>
  </joint>
  <link name="horizontal_slider">
    <inertial>
      <mass value="0.05"/>
      <origin rpy="0 0 0" xyz="0 0 0"/>
      <inertia ixx="0.1" ixy="0" ixz="0" iyy="0.1" iyz="0" izz="0.1"/>
    </inertial>
    <collision>
      <origin rpy="0 0 0" xyz="0 0 0"/>
      <geometry>
        <box size="0.6 0.04 0.04"/>
      </geometry>
    </collision>
    <visual>
      <origin rpy="0 0 0" xyz="0 0 0"/>
      <geometry>
        <box size="0.6 0.04 0.04"/>
      </geometry>
    </visual>
  </link>
  <joint name="slider_on_bot" type="prismatic">
    <origin rpy="0 0 0" xyz="0 0 0.1"/>
    <parent link="base_link"/>
    <child link="horizontal_slider"/>
    <axis rpy="0 0 0" xyz="1 0 0"/>
    <limit effort="10000" velocity="1000"/>
    <joint_properties damping="1.0" friction="1.0"/>
  </joint>
  <link name="palm">
    <inertial>
      <mass value="0.5"/>
      <origin rpy="0 0 0" xyz="0 0 0.05"/>
      <inertia ixx="0.01" ixy="0" ixz="0" iyy="0.01" iyz="0" izz="0.01"/>
    </inertial>
    <collision>
      <origin rpy="0 0 0" xyz="0 0 0"/>
      <geometry>
        <box size="0.1 0.2 0.1"/>
      </geometry>
    </collision>
    <visual>
      <origin rpy="0 0 0" xyz="0 0 0"/>
      <geometry>
        <box size="0.1 0.2 0.1"/>
      </geometry>
    </visual>
  </link>
  <link name="left_finger">
    <inertial>
      <mass value="0.1"/>
      <origin rpy="0 0 0" xyz="0 0 0"/>
      <inertia ixx="0.01" ixy="0" ixz="0" iyy="0.01" iyz="0" izz="0"/>
    </inertial>
    <collision>
      <origin rpy="0 0 0" xyz="0 0 0"/>
      <geometry>
        <box size="0.1 0.3 0.1"/>
      </geometry>
    </collision>
    <visual>
      <origin rpy="0 0 0" xyz="0 0 0"/>
      <geometry>
        <box size="0.1 0.3 0.1"/>
      </geometry>
    </visual>
  </link>
  <link name="right_finger">
    <inertial>
      <mass value="0.1"/>
      <origin rpy="0 0 0" xyz="0 0 0"/>
      <inertia ixx="0.01" ixy="0" ixz="0" iyy="0.01" iyz="0" izz="0"/>
    </inertial>
    <collision>
      <origin rpy="0 0 -0.78539" xyz="0 0 0"/>
      <geometry>
        <box size="0.1 0.3 0.1"/>
      </geometry>
    </collision>
    <visual>
      <origin rpy="0 0 0" xyz="0 0 0"/>
      <geometry>
        <box size="0.1 0.3 0.1"/>
      </geometry>
    </visual>
  </link>
  <link name="left_finger_tip">
    <inertial>
      <origin rpy="0 0 0" xyz="0 0 0"/>
      <mass value="0.1"/>
      <inertia ixx="0.01" ixy="0" ixz="0" iyy="0.01" iyz="0" izz="0.01"/>
    </inertial>
    <collision>
      <origin rpy="0 0 0" xyz="0 0 0"/>
      <geometry>
        <box size="0.1 0.2 0.1"/>
      </geometry>
    </collision>
    <visual>
      <origin rpy="0 0 0" xyz="0 0 0"/>
      <geometry>
        <box size="0.1 0.2 0.1"/>
      </geometry>
    </visual>
  </link>
  <link name="right_finger_tip">
    <inertial>
      <origin rpy="0 0 0" xyz="0 0 0"/>
      <mass value="0.1"/>
      <inertia ixx="0.01" ixy="0" ixz="0" iyy="0.01" iyz="0" izz="0.01"/>
    </inertial>
    <collision>
      <origin rpy="0 0 0" xyz="0 0 0"/>
      <geometry>
        <box size="0.1 0.2 0.1"/>
      </geometry>
    </collision>
    <visual>
      <origin rpy="0 0 0" xyz="0 0 0"/>
      <geometry>
        <box size="0.1 0.2 0.1"/>
      </geometry>
    </visual>
  </link>
  <joint name="palm_left_finger" type="revolute">
    <origin rpy="0 0 0" xyz="0 -0.15 0"/>
    <child link="left_finger"/>
    <parent link="palm"/>
    <axis xyz="0 0 1"/>
    <limit effort="1000" lower="-0.4" upper="-0.4" velocity="1000"/>
  </joint>
  <joint name="left_finger_tip" type="revolute">
    <origin rpy="0 0 0" xyz="0 0.1 0"/>
    <child link="left_finger_tip"/>
    <parent link="left_finger"/>
    <axis xyz="0 0 1"/>
    <limit effort="1000" lower="-0.4" upper="-0.4" velocity="1000"/>
  </joint>
  <joint name="palm_right_finger" type="revolute">
    <origin rpy="0 0 0" xyz="0 0.15 0"/>
    <child link="right_finger"/>
    <parent link="palm"/>
    <axis xyz="0 0 1"/>
    <limit effort="1000" lower="-0.4" upper="-0.4" velocity="1000"/>
  </joint>
  <joint name="right_finger_tip" type="revolute">
    <origin rpy="0 0 0" xyz="0 0.1 0"/>
    <child link="right_finger_tip"/>
    <parent link="right_finger"/>
    <axis xyz="0 0 1"/>
    <limit effort="1000" lower="-0.4" upper="-0.4" velocity="1000"/>
  </joint>
  <joint name="palm_slider" type="fixed">
    <origin rpy="0 0 0" xyz="0.3 0 0"/>
    <child link="palm"/>
    <parent link="horizontal_slider"/>
  </joint>
</robot>

